<?xml version='1.0'?>
<sdf version='1.9'>
  <model name="rosebot">
	<static>false</static>
	<link name='chassis'>
	    <pose>0 0 0.07 0 0 0</pose>

	    <collision name='collision'>
	      <geometry>
		<box>
		  <size>.2 .2 .3</size>
		</box>
	      </geometry>
	    </collision>

	    <visual name='visual'>
	      <geometry>
		<box>
		  <size>.2 .2 .3</size>
		</box>
	      </geometry>
	    </visual>

	    <collision name='caster_collision'>
		    <pose>-0.1 0 -0.145 0 0 0</pose>
		    <geometry>
			<sphere>
			<radius>.025</radius>
		      </sphere>
		    </geometry>

		    <surface>
		      <friction>
			<ode>
			  <mu>0</mu>
			  <mu2>0</mu2>
			  <slip1>1.0</slip1>
			  <slip2>1.0</slip2>
			</ode>
		      </friction>
		    </surface>
	  </collision>

	  <visual name='caster_visual'>
	    <pose>-0.1 0 -0.145 0 0 0</pose>
	    <geometry>
	      <sphere>
		<radius>.025</radius>
	      </sphere>
	    </geometry>
	  </visual>
	</link>
	<link name="left_wheel">
		<pose>0.05 0.115 -0.05 0 1.5707 1.5707</pose>
		<collision name="collision">
		  <geometry>
		    <cylinder>
		      <radius>.05</radius>
		      <length>.02</length>
		    </cylinder>
		  </geometry>
		</collision>
		<visual name="visual">
		  <geometry>
		    <cylinder>
		      <radius>.05</radius>
		      <length>.02</length>
		    </cylinder>
		  </geometry>
		</visual>
	</link>
	<link name="right_wheel">
		<pose>0.05 -0.115 -0.05 0 1.5707 1.5707</pose>
		<collision name="collision">
		  <geometry>
		    <cylinder>
		      <radius>.05</radius>
		      <length>.02</length>
		    </cylinder>
		  </geometry>
		</collision>
		<visual name="visual">
		  <geometry>
		    <cylinder>
		      <radius>.05</radius>
		      <length>.02</length>
		    </cylinder>
		  </geometry>
		</visual>
	</link>
 	<joint type="revolute" name="left_wheel_hinge">
		<pose>0 0 -0.01 0 0 0</pose>
		<child>left_wheel</child>
		<parent>chassis</parent>
		<axis>
		  <xyz>0 0 1</xyz>
		</axis>
      </joint>

      <joint type="revolute" name="right_wheel_hinge">
        <pose>0 0 0.01 0 0 0</pose>
        <child>right_wheel</child>
        <parent>chassis</parent>
        <axis>
          <xyz>0 0 1</xyz>
        </axis>
      </joint>
  </model>
</sdf>
